<?xml version="1.0"?>
<robot xmlns:sensor="http://playerstage.sourceforge.net/gazebo/xmlschema/#sensor"
       xmlns:controller="http://playerstage.sourceforge.net/gazebo/xmlschema/#controller"
       xmlns:interface="http://playerstage.sourceforge.net/gazebo/xmlschema/#interface">

  <property name="M_PI" value="3.1415926535897931" />
 

  <macro name="m3_neck" params="side parent reflect *origin">
    
    <joint name="head_j0" type="revolute">
      <axis xyz="0 -1 0" />
      <insert_block name="origin" /> <!-- transform from parent link to this joint frame -->
      <parent link="${parent}"/>
      <child link="neck_tilt"/>
      <limit effort="100" velocity="${20.0*M_PI/180}" lower="${-18.0*M_PI/180}" upper="${1.0*M_PI/180}" />
    </joint>
    <link name="neck_tilt">
      <inertial>
        <mass value="0.940" />
	<origin xyz="0.000061 0.003310 0.028798"/>
	<inertia ixx="0.001395"
	iyy="0.001345"
	izz="0.000392"
	ixy="-0.000000"
	ixz="-0.000000"
	iyz="-0.000085" />
      </inertial>

      <visual>
	      <material name="GreyA" />
	      <origin xyz="0 0 0" rpy="0 0 0 " />
	      <geometry name="neck_tilt_geom">		
		      <mesh filename="package://${MESH}/S2R1/S2R1_SH1_neckTilt.dae" />
	      </geometry>  
      </visual>

      <collision>
	      <origin xyz="0 0 0" rpy="0.0 0.0 0.0 " />
	      <geometry name="neck_tilt_geom_collison">
		      <mesh filename="package://${MESH_COLL}/S2R1/S2R1_SH1_neckTilt.stl" />
	      </geometry>
      </collision>
    </link>

     
    <joint name="head_j1" type="revolute">
      <axis xyz="0 0 1"/>
     <limit effort="100" velocity="${75*M_PI/180}" lower="${-56.0*M_PI/180}" upper="${56.0*M_PI/180}" />    
      <origin xyz="0 0 0.13849" rpy="0 0 0" />
      <parent link="neck_tilt"/>
      <child link="neck_roll"/>
    </joint>
    <link name="neck_roll">

      <inertial>
        <mass value="0.409" />
	<origin xyz="0.0 0.0 0.0"/>
	<inertia ixx="0.0"
	iyy="0.0"
	izz="0.0"
	ixy="0.0"
	ixz="0.0"
	iyz="0.0" />
      </inertial>

      <visual>
	      <material name="GreyB" />
	      <origin xyz="0 0 0" rpy="0 0 0 " />
	      <geometry name="neck_roll_geom">
		      <mesh filename="package://${MESH}/S2R1/S2R1_SH2_neckRoll.dae" />
	      </geometry>  
      </visual>
      
      <collision>
	      <origin xyz="0 0 0" rpy="0.0 0.0 0.0 " />
	      <geometry name="S2R1_SH2_neckRoll_collision">
		      <box size="0.01 0.01 0.01" />
	      </geometry>
      </collision>
    </link>


</macro>


  <macro name="m3_head" params="side parent reflect *origin">
    <m3_neck side="${side}" reflect="${reflect}" parent="${parent}">
      <insert_block name="origin" />
    </m3_neck>
  </macro>


</robot>
