<?xml version="1.0"?>
<robot xmlns:sensor="http://playerstage.sourceforge.net/gazebo/xmlschema/#sensor"
       xmlns:controller="http://playerstage.sourceforge.net/gazebo/xmlschema/#controller"
       xmlns:interface="http://playerstage.sourceforge.net/gazebo/xmlschema/#interface">
  

  <property name="M_PI" value="3.1415926535897931" />


  <macro name="meka_zlift" params="side parent reflect *origin">

    <!-- Shoulder pan -->
    <joint name="zlift_joint" type="prismatic">
      <axis xyz="0 0 1" />
      <insert_block name="origin" /> <!-- transform from parent link to this joint frame -->
      <parent link="${parent}"/>
      <child link="zlift_link"/>
      <limit lower="${0.0*M_PI/180.0}"  upper="${31965.0*M_PI/180.0}"
             effort="30" velocity="${3.48}" />

      <dynamics damping="10.0" />

      <safety_controller k_position="100" k_velocity="10"
                         soft_lower_limit="${reflect*M_PI/4-1.5+0.15}"
                         soft_upper_limit="${reflect*M_PI/4+1.5-0.15}" />      
    </joint>
    
    <link name="zlift_link">
      <inertial>
        <mass value="25.799322" />
        <origin xyz="0.0 0.0 0.0" rpy="0 0 0"/>
        <inertia ixx="0.866179142480"  ixy="-0.06086507933"  ixz="-0.12118061183"
                 iyy="0.87421714893"  iyz="-0.05886609911"
                 izz="0.27353821674" />
      </inertial>

      <visual>
	      <material name="GreyA" />
	      <origin xyz="0 0 0" rpy="0 0 0 " />
	      <geometry name="z_lift_geom">
		      <mesh filename="package://${MESH}/B1R1/MB1_00_011_festo-chest_mount_assy+spacer.dae" />
	      </geometry>  
      </visual>

      <collision>
	      <origin xyz="0 0 0" rpy="0.0 0.0 0.0 " />
	      <geometry name="z_lift_geom_collision_geom">
		      <mesh filename="package://${MESH_COLL}/B1R1/MB1_00_011_festo-chest_mount_assy+spacer.stl" />
	      </geometry>
      </collision>
    </link>
  <link name="upper">
	  <inertial>
		  <mass value="1000" />
		  <origin xyz="0 0 0" />
		  <inertia ixx="1000"  ixy="0"  ixz="0" iyy="1000" iyz="0" izz="1000" />
	  </inertial>
	  <visual>
		  <material name="GreyC" />
		  <origin xyz="0 0 0" rpy="0 0 0" />
		  <geometry name="upper_geom">
			  <mesh filename="package://${MESH}/A2R3/A2R3_T4_Chest_Neck.dae" />
		  </geometry>
		  <!--material name="Blue" /-->
	  </visual>
	  <collision>
		  <origin xyz="0 0 0" rpy="0.0 0.0 0.0 " />
		  <geometry name="upper_collision_geom">
			  <mesh filename="package://${MESH_COLL}/A2R3/A2R3_T4_Chest_Neck.stl" />
		  </geometry>
	  </collision>
  </link>
    <joint name="chest_joint" type="fixed">
	<origin xyz="0 0 -0.03" rpy="0 0 0" />
	<parent link="zlift_link" />
	<child link="upper" />
    </joint>
    <joint name="origin_joint" type="fixed">
	<origin xyz="0 0 0.2337" rpy="0 0 0" />
	<parent link="upper" />
	<child link="T0" />
    </joint>
    <link name="T0"/>
  </macro>


</robot>
